<?xml version="1.0" ?>
<!-- =================================================================================== -->
<!-- |    This document was autogenerated by xacro from woody.gazebo.xacro             | -->
<!-- |    EDITING THIS FILE BY HAND IS NOT RECOMMENDED                                 | -->
<!-- =================================================================================== -->
<robot name="woody" xmlns:xacro="http://ros.org/wiki/xacro">
  <!-- Import Files -->
  <material name="white">
    <color rgba="1.0 1.0 1.0 1.0"/>
  </material>
  <material name="black">
    <color rgba="0.0 0.0 0.0 1.0"/>
  </material>
  <material name="red">
    <color rgba="0.8 0.0 0.0 1.0"/>
  </material>
  <material name="green">
    <color rgba="0.0 0.8 0.0 1.0"/>
  </material>
  <material name="blue">
    <color rgba="0.0 0.0 0.8 1.0"/>
  </material>
  <material name="solidworks_default">
    <color rgba="0.752941176471 0.752941176471 0.752941176471 1.0"/>
  </material>
  <material name="base">
    <color rgba="0.0 0.0 0.0 1.0"/>
  </material>
  <material name="side">
    <color rgba="0.0 0.0 0.0 1.0"/>
  </material>
  <material name="wheel">
    <color rgba="0.0196078431373 0.0196078431373 0.0 1.0"/>
  </material>
  <link name="base_link">
    <inertial>
      <origin xyz="-0.00968 -0.00122 0.19369"/>
      <mass value="8.25079"/>
      <inertia ixx="0.112701442" ixy="-0.000233829" ixz="-0.014681510" iyy="0.096589855" iyz="-0.000177925" izz="0.083438037"/>
    </inertial>
    <visual>
      <geometry>
        <mesh filename="package://pandora_robots_description/woody/meshes/base_link.dae"/>
      </geometry>
      <material name="base"/>
    </visual>
    <collision>
      <geometry>
        <mesh filename="package://pandora_robots_description/woody/meshes/base_link.stl"/>
      </geometry>
    </collision>
  </link>
  <link name="miniitx">
    <inertial>
      <origin xyz="0.0 0.0 0.0"/>
      <mass value="0.589"/>
      <inertia ixx="0.0014381417" ixy="0.0" ixz="0.0" iyy="0.0019829667" iyz="0.0" izz="0.0033818417"/>
    </inertial>
  </link>
  <joint name="miniitx_joint" type="fixed">
    <parent link="base_link"/>
    <child link="miniitx"/>
    <origin rpy="0.0 0.0 0.0" xyz="0.03895 0.0 0.16181"/>
  </joint>
  <link name="ssd">
    <inertial>
      <origin xyz="0.0 0.0 0.0"/>
      <mass value="0.078"/>
      <inertia ixx="0.0000325" ixy="0.0" ixz="0.0" iyy="0.00006565" iyz="0.0" izz="0.00009685"/>
    </inertial>
  </link>
  <joint name="ssd_joint" type="fixed">
    <parent link="base_link"/>
    <child link="ssd"/>
    <origin rpy="1.570796327 0.0 0.0" xyz="0.059 -0.097 0.181"/>
  </joint>
  <link name="raspberry">
    <inertial>
      <origin rpy="0.0 0.0 0.0" xyz="0.0 0.0 0.0"/>
      <mass value="0.062"/>
      <inertia ixx="2.85458333333e-05" ixy="0.0" ixz="0.0" iyy="4.98583333333e-05" iyz="0.0" izz="7.19458333333e-05"/>
    </inertial>
  </link>
  <joint name="raspberry_joint" type="fixed">
    <parent link="base_link"/>
    <child link="raspberry"/>
    <origin rpy="0.0 0.0 0.0" xyz="0.071 0.076 0.24"/>
  </joint>
  <link name="arm">
    <inertial>
      <origin rpy="0.0 0.0 0.0" xyz="0.0 0.0 0.0"/>
      <mass value="0.05"/>
      <inertia ixx="4.88166666667e-05" ixy="0.0" ixz="0.0" iyy="2.08166666667e-05" iyz="0.0" izz="6.21333333333e-05"/>
    </inertial>
  </link>
  <joint name="arm_joint" type="fixed">
    <parent link="base_link"/>
    <child link="arm"/>
    <origin rpy="0.0 0.0 1.570796327" xyz="-0.052 0.002 0.245"/>
  </joint>
  <link name="epos">
    <inertial>
      <origin xyz="0.0 0.0 0.0"/>
      <mass value="0.136"/>
      <inertia ixx="0.0002266667" ixy="0.0" ixz="0.0" iyy="6.8283E-005" iyz="0.0" izz="0.0002858833"/>
    </inertial>
  </link>
  <joint name="epos_joint" type="fixed">
    <parent link="base_link"/>
    <child link="epos"/>
    <origin rpy="0.0 0.0 0.0" xyz="-0.08263 0.0 0.03222"/>
  </joint>
  <link name="psu">
    <inertial>
      <origin xyz="0.0 0.0 0.0"/>
      <mass value="0.178"/>
      <inertia ixx="0.0002241168" ixy="0.0" ixz="0.0" iyy="0.0001828208" iyz="0.0" izz="0.0004002627"/>
    </inertial>
  </link>
  <joint name="psu_joint" type="fixed">
    <parent link="base_link"/>
    <child link="psu"/>
    <origin rpy="0.0 0.0 0.0" xyz="0.073 0.0 0.11023"/>
  </joint>
  <link name="motor_battery">
    <inertial>
      <origin xyz="0.0 0.0 0.0"/>
      <mass value="0.8"/>
      <inertia ixx="0.0003576" ixy="0.0" ixz="0.0" iyy="0.0016806" iyz="0.0" izz="0.0015582"/>
    </inertial>
  </link>
  <joint name="motor_battery_joint" type="fixed">
    <parent link="base_link"/>
    <child link="motor_battery"/>
    <origin rpy="0.0 0.0 0.0" xyz="0.10395 0.027 0.04822"/>
  </joint>
  <link name="pc_battery">
    <inertial>
      <origin xyz="0.0 0.0 0.0"/>
      <mass value="0.8"/>
      <inertia ixx="0.0003576" ixy="0.0" ixz="0.0" iyy="0.0016806" iyz="0.0" izz="0.0015582"/>
    </inertial>
  </link>
  <joint name="pc_battery_joint" type="fixed">
    <parent link="base_link"/>
    <child link="pc_battery"/>
    <origin rpy="0.0 0.0 0.0" xyz="0.10395 -0.027 0.04822"/>
  </joint>
  <link name="cables">
    <inertial>
      <origin xyz="0.0 0.0 0.0"/>
      <mass value="0.6"/>
      <inertia ixx="0.00001" ixy="0.0" ixz="0.0" iyy="0.00001" iyz="0.0" izz="0.00001"/>
    </inertial>
  </link>
  <joint name="cables_joint" type="fixed">
    <parent link="base_link"/>
    <child link="cables"/>
    <origin rpy="0.0 0.0 0.0" xyz="0.0 0.0 0.1"/>
  </joint>
  <link name="axis">
    <inertial>
      <origin rpy="0.0 0.0 0.0" xyz="0.0 0.0 0.0"/>
      <mass value="0.446"/>
      <inertia ixx="0.0027499245" ixy="0.0" ixz="0.0" iyy="0.0027499245" iyz="0.0" izz="0.0002007"/>
    </inertial>
  </link>
  <joint name="axis_joint" type="fixed">
    <parent link="base_link"/>
    <child link="axis"/>
    <origin rpy="0.0 0.0 0.0" xyz="0.0 0.0 0.0"/>
  </joint>
  <link name="imu">
    <inertial>
      <origin rpy="0.0 0.0 0.0" xyz="0.0 0.0 0.0"/>
      <mass value="0.05"/>
      <inertia ixx="1.08375e-05" ixy="0.0" ixz="0.0" iyy="1.59375e-05" iyz="0.0" izz="2.1975e-05"/>
    </inertial>
  </link>
  <joint name="imu_joint" type="fixed">
    <parent link="base_link"/>
    <child link="imu"/>
    <origin rpy="0.0 0.0 0.0" xyz="0.09013 -0.08006 0.24281"/>
  </joint>
  <link name="left_side_link">
    <inertial>
      <origin xyz="-8.21e-06 0.00188403 -0.04035954"/>
      <mass value="1.81542748"/>
      <inertia ixx="0.000596450" ixy="-0.000025495" ixz="5.73e-07" iyy="0.016130501" iyz="-6.6532e-05" izz="0.015779275"/>
    </inertial>
    <visual>
      <origin rpy="0.0 0.0 0.0" xyz="0.0 0.0 0.0"/>
      <geometry>
        <mesh filename="package://pandora_robots_description/woody/meshes/side_link.dae"/>
      </geometry>
      <material name="side"/>
    </visual>
    <collision>
      <origin rpy="0.0 0.0 0.0" xyz="0.0 0.0 0.0"/>
      <geometry>
        <mesh filename="package://pandora_robots_description/woody/meshes/side_link.stl"/>
      </geometry>
    </collision>
  </link>
  <joint name="left_side_joint" type="revolute">
    <parent link="base_link"/>
    <child link="left_side_link"/>
    <origin rpy="0.0 0.0 0.0" xyz="0.0 0.10314 0.0"/>
    <axis xyz="0 1 0"/>
    <dynamics damping="0.0"/>
    <limit effort="150.0" lower="-0.785" upper="0.785" velocity="150.0"/>
  </joint>
  <link name="right_side_link">
    <inertial>
      <origin xyz="8.21e-06 -0.00188403 -0.04035954"/>
      <mass value="1.81542748"/>
      <inertia ixx="0.000596450" ixy="-0.000025495" ixz="-5.73e-07" iyy="0.016130501" iyz="6.6532e-05" izz="0.015779275"/>
    </inertial>
    <visual>
      <origin rpy="0.0 0.0 3.141592654" xyz="0.0 0.0 0.0"/>
      <geometry>
        <mesh filename="package://pandora_robots_description/woody/meshes/side_link.dae"/>
      </geometry>
      <material name="side"/>
    </visual>
    <collision>
      <origin rpy="0.0 0.0 3.141592654" xyz="0.0 0.0 0.0"/>
      <geometry>
        <mesh filename="package://pandora_robots_description/woody/meshes/side_link.stl"/>
      </geometry>
    </collision>
  </link>
  <joint name="right_side_joint" type="revolute">
    <parent link="base_link"/>
    <child link="right_side_link"/>
    <origin rpy="0.0 0.0 0.0" xyz="0.0 -0.10314 0.0"/>
    <axis xyz="0 1 0"/>
    <dynamics damping="0.0"/>
    <limit effort="150.0" lower="-0.785" upper="0.785" velocity="150.0"/>
  </joint>
  <link name="left_front_wheel_link">
    <inertial>
      <origin xyz="-2.2235e-05 -0.00052624 2.4287E-05"/>
      <mass value="1.5"/>
      <inertia ixx="0.0040302" ixy="7.250E-08" ixz="5.2121e-07" iyy="0.0067791" iyz="-7.9189e-08" izz="0.0040286"/>
    </inertial>
    <visual>
      <origin rpy="0.0 0.0 0.0" xyz="0.0 0.0 0.0"/>
      <geometry>
        <mesh filename="package://pandora_robots_description/woody/meshes/wheel_link.dae"/>
      </geometry>
      <material name="wheel"/>
    </visual>
    <collision>
      <origin rpy="0.0 0.0 0.0" xyz="0.0 0.0 0.0"/>
      <geometry>
        <mesh filename="package://pandora_robots_description/woody/meshes/wheel_link.stl"/>
      </geometry>
    </collision>
  </link>
  <joint name="left_front_wheel_joint" type="continuous">
    <parent link="left_side_link"/>
    <child link="left_front_wheel_link"/>
    <origin rpy="0.0 0.0 0.0" xyz="0.17339 0.06886 -0.052795"/>
    <axis xyz="0 1 0"/>
    <dynamics damping="0.0"/>
    <limit effort="100.0" velocity="100.0"/>
  </joint>
  <link name="left_rear_wheel_link">
    <inertial>
      <origin xyz="-2.2235e-05 -0.00052624 2.4287E-05"/>
      <mass value="1.5"/>
      <inertia ixx="0.0040302" ixy="7.250E-08" ixz="5.2121e-07" iyy="0.0067791" iyz="-7.9189e-08" izz="0.0040286"/>
    </inertial>
    <visual>
      <origin rpy="0.0 0.0 0.0" xyz="0.0 0.0 0.0"/>
      <geometry>
        <mesh filename="package://pandora_robots_description/woody/meshes/wheel_link.dae"/>
      </geometry>
      <material name="wheel"/>
    </visual>
    <collision>
      <origin rpy="0.0 0.0 0.0" xyz="0.0 0.0 0.0"/>
      <geometry>
        <mesh filename="package://pandora_robots_description/woody/meshes/wheel_link.stl"/>
      </geometry>
    </collision>
  </link>
  <joint name="left_rear_wheel_joint" type="continuous">
    <parent link="left_side_link"/>
    <child link="left_rear_wheel_link"/>
    <origin rpy="0.0 0.0 0.0" xyz="-0.17339 0.06886 -0.052795"/>
    <axis xyz="0 1 0"/>
    <dynamics damping="0.0"/>
    <limit effort="100.0" velocity="100.0"/>
  </joint>
  <link name="right_front_wheel_link">
    <inertial>
      <origin xyz="2.2235e-05 0.00052624 2.4287E-05"/>
      <mass value="1.5"/>
      <inertia ixx="0.0040302" ixy="7.250E-08" ixz="-5.2121e-07" iyy="0.0067791" iyz="7.9189e-08" izz="0.0040286"/>
    </inertial>
    <visual>
      <origin rpy="0.0 0.0 3.141592654" xyz="0.0 0.0 0.0"/>
      <geometry>
        <mesh filename="package://pandora_robots_description/woody/meshes/wheel_link.dae"/>
      </geometry>
      <material name="wheel"/>
    </visual>
    <collision>
      <origin rpy="0.0 0.0 3.141592654" xyz="0.0 0.0 0.0"/>
      <geometry>
        <mesh filename="package://pandora_robots_description/woody/meshes/wheel_link.stl"/>
      </geometry>
    </collision>
  </link>
  <joint name="right_front_wheel_joint" type="continuous">
    <parent link="right_side_link"/>
    <child link="right_front_wheel_link"/>
    <origin rpy="0.0 0.0 0.0" xyz="0.17339 -0.06886 -0.052795"/>
    <axis xyz="0 1 0"/>
    <dynamics damping="0.0"/>
    <limit effort="100.0" velocity="100.0"/>
  </joint>
  <link name="right_rear_wheel_link">
    <inertial>
      <origin xyz="2.2235e-05 0.00052624 2.4287E-05"/>
      <mass value="1.5"/>
      <inertia ixx="0.0040302" ixy="7.250E-08" ixz="-5.2121e-07" iyy="0.0067791" iyz="7.9189e-08" izz="0.0040286"/>
    </inertial>
    <visual>
      <origin rpy="0.0 0.0 3.141592654" xyz="0.0 0.0 0.0"/>
      <geometry>
        <mesh filename="package://pandora_robots_description/woody/meshes/wheel_link.dae"/>
      </geometry>
      <material name="wheel"/>
    </visual>
    <collision>
      <origin rpy="0.0 0.0 3.141592654" xyz="0.0 0.0 0.0"/>
      <geometry>
        <mesh filename="package://pandora_robots_description/woody/meshes/wheel_link.stl"/>
      </geometry>
    </collision>
  </link>
  <joint name="right_rear_wheel_joint" type="continuous">
    <parent link="right_side_link"/>
    <child link="right_rear_wheel_link"/>
    <origin rpy="0.0 0.0 0.0" xyz="-0.17339 -0.06886 -0.052795"/>
    <axis xyz="0 1 0"/>
    <dynamics damping="0.0"/>
    <limit effort="100.0" velocity="100.0"/>
  </joint>
  <link name="laser_roll_servo_link">
    <inertial>
      <origin xyz="0.00234 0.01566 -0.0002"/>
      <mass value="0.057"/>
      <inertia ixx="1.769375e-05" ixy="0.0" ixz="0.0" iyy="1.38035e-05" iyz="0.0" izz="1.985975e-05"/>
    </inertial>
    <visual>
      <geometry>
        <mesh filename="package://pandora_sensors_description/laser/meshes/roll_servo_motor.dae"/>
      </geometry>
    </visual>
    <collision>
      <origin rpy="0 0 0" xyz="0.00165 0.0135 -0.0015"/>
      <geometry>
        <box size="0.041 0.050 0.035"/>
      </geometry>
    </collision>
  </link>
  <link name="laser_pitch_servo_link">
    <inertial>
      <origin xyz="-0.00022 0.00223 0.00708"/>
      <mass value="0.057"/>
      <inertia ixx="1.985975e-05" ixy="0.0" ixz="0.0" iyy="1.769375e-05" iyz="0.0" izz="1.38035e-05"/>
    </inertial>
    <visual>
      <geometry>
        <mesh filename="package://pandora_sensors_description/laser/meshes/pitch_servo_motor.dae"/>
      </geometry>
    </visual>
    <collision>
      <origin rpy="0 0 0" xyz="-0.00149 0.0 0.0093"/>
      <geometry>
        <box size="0.035 0.041 0.050"/>
      </geometry>
    </collision>
  </link>
  <link name="laser_main_link">
    <inertial>
      <origin xyz="0.00041 -0.00007 0.04539"/>
      <mass value="0.16"/>
      <inertia ixx="0.00856801333333" ixy="0.0" ixz="0.0" iyy="0.00856405333333" iyz="0.0" izz="6.54e-05"/>
    </inertial>
    <visual>
      <geometry>
        <mesh filename="package://pandora_sensors_description/laser/meshes/hokuyo_urg_04lx.dae"/>
      </geometry>
    </visual>
    <collision>
      <origin rpy="0 0 0" xyz="0.00078 -0.0001 0.04595"/>
      <geometry>
        <box size="0.048 0.051 0.114"/>
      </geometry>
    </collision>
  </link>
  <joint name="laser_servo_parent_joint" type="fixed">
    <parent link="base_link"/>
    <child link="laser_roll_servo_link"/>
    <origin rpy="0.0 0.0 0.035" xyz="0.19015 -0.00248 0.12722"/>
  </joint>
  <joint name="laser_roll_joint" type="revolute">
    <parent link="laser_roll_servo_link"/>
    <child link="laser_pitch_servo_link"/>
    <origin rpy="0 0 0" xyz="0.03999 0.0 0.0"/>
    <axis xyz="1 0 0"/>
    <limit effort="50" lower="-0.523" upper="0.523" velocity="50.0"/>
  </joint>
  <joint name="laser_pitch_joint" type="revolute">
    <parent link="laser_pitch_servo_link"/>
    <child link="laser_main_link"/>
    <origin rpy="0 0 0" xyz="0.0 0.0 0.02276"/>
    <axis xyz="0 1 0"/>
    <limit effort="50" lower="-0.523" upper="0.523" velocity="50.0"/>
  </joint>
  <link name="laser_link">
    <inertial>
      <origin xyz="0.0 0.0 0.0"/>
      <mass value="0.001"/>
      <inertia ixx="1.0E-6" ixy="0" ixz="0" iyy="1.0E-6" iyz="0" izz="1.0E-6"/>
    </inertial>
  </link>
  <joint name="laser_joint" type="fixed">
    <parent link="laser_main_link"/>
    <child link="laser_link"/>
    <origin rpy="0 0 0" xyz="0.0 0.0 0.089"/>
  </joint>
  <link name="kinect_yaw_servo_link">
    <inertial>
      <origin xyz="-0.01316 0.00002 0.00093"/>
      <mass value="0.055"/>
      <inertia ixx="1.56979166667e-05" ixy="0.0" ixz="0.0" iyy="2.24629166667e-05" iyz="0.0" izz="1.61516666667e-05"/>
    </inertial>
    <visual>
      <geometry>
        <mesh filename="package://pandora_sensors_description/kinect/meshes/yaw_servo_motor.dae"/>
      </geometry>
    </visual>
    <collision>
      <origin xyz="-0.0135 0.0 -0.0028"/>
      <geometry>
        <box size="0.050 0.032 0.049"/>
      </geometry>
    </collision>
  </link>
  <link name="kinect_pitch_servo_link">
    <inertial>
      <origin xyz="0.0001 0.00217 -0.01699"/>
      <mass value="0.063"/>
      <inertia ixx="3.455025e-05" ixy="0.0" ixz="0.0" iyy="3.543225e-05" iyz="0.0" izz="1.85325e-05"/>
    </inertial>
    <visual>
      <geometry>
        <mesh filename="package://pandora_sensors_description/kinect/meshes/pitch_servo_motor.dae"/>
      </geometry>
    </visual>
    <collision>
      <origin xyz="0.0055 0.0 -0.0405"/>
      <geometry>
        <box size="0.043 0.041 0.104"/>
      </geometry>
    </collision>
  </link>
  <link name="kinect_platform_link">
    <inertial>
      <origin xyz="0.00926 -0.00059 -0.00362"/>
      <mass value="0.07"/>
      <inertia ixx="8.56858333333e-05" ixy="0.0" ixz="0.0" iyy="6.00191666667e-05" iyz="0.0" izz="0.000142333333333"/>
    </inertial>
    <visual>
      <geometry>
        <mesh filename="package://pandora_sensors_description/kinect/meshes/platform.dae"/>
      </geometry>
    </visual>
    <collision>
      <origin rpy="0 0 0" xyz="0.012 -0.00101 -0.019"/>
      <geometry>
        <box size="0.100 0.120 0.041"/>
      </geometry>
    </collision>
  </link>
  <link name="kinect_link">
    <inertial>
      <origin xyz="0.0000013 0.0 0.0000014"/>
      <mass value="0.2268"/>
      <inertia ixx="0.0006241725" ixy="0.0" ixz="0.0" iyy="3.63069e-05" iyz="0.0" izz="0.0006368544"/>
    </inertial>
    <visual>
      <geometry>
        <mesh filename="package://pandora_sensors_description/kinect/meshes/asus_xtion_pro_live.dae"/>
      </geometry>
    </visual>
    <collision>
      <origin rpy="0 0 0" xyz="-0.00075 -0.00048 0.00016"/>
      <geometry>
        <box size="0.036 0.180 0.025"/>
      </geometry>
    </collision>
  </link>
  <joint name="kinect_servo_parent_joint" type="fixed">
    <parent link="base_link"/>
    <child link="kinect_yaw_servo_link"/>
    <origin rpy="0.0 0.0 0.0" xyz="0.11999 0.031 0.25781"/>
  </joint>
  <joint name="kinect_yaw_joint" type="revolute">
    <parent link="kinect_yaw_servo_link"/>
    <child link="kinect_pitch_servo_link"/>
    <origin rpy="0.0 0.0 0.0" xyz="0.0 0.0 0.06749"/>
    <axis xyz="0 0 1"/>
    <limit effort="50" lower="-1.308" upper="1.308" velocity="50.0"/>
  </joint>
  <joint name="kinect_pitch_joint" type="revolute">
    <parent link="kinect_pitch_servo_link"/>
    <child link="kinect_platform_link"/>
    <axis xyz="0 1 0"/>
    <limit effort="50" lower="-0.785" upper="0.785" velocity="50.0"/>
  </joint>
  <joint name="kinect_platform_joint" type="fixed">
    <parent link="kinect_platform_link"/>
    <child link="kinect_link"/>
    <origin rpy="0.0 0.0 0.0" xyz="0.03261 -0.00101 0.04261"/>
  </joint>
  <link name="kinect_frame">
    <inertial>
      <origin xyz="0.0 0.0 0.0"/>
      <mass value="0.001"/>
      <inertia ixx="1.0E-6" ixy="0" ixz="0" iyy="1.0E-6" iyz="0" izz="1.0E-6"/>
    </inertial>
  </link>
  <link name="kinect_optical_frame">
    <inertial>
      <origin xyz="0.0 0.0 0.0"/>
      <mass value="0.001"/>
      <inertia ixx="1.0E-6" ixy="0" ixz="0" iyy="1.0E-6" iyz="0" izz="1.0E-6"/>
    </inertial>
  </link>
  <link name="kinect_depth_frame">
    <inertial>
      <origin xyz="0.0 0.0 0.0"/>
      <mass value="0.001"/>
      <inertia ixx="1.0E-6" ixy="0" ixz="0" iyy="1.0E-6" iyz="0" izz="1.0E-6"/>
    </inertial>
  </link>
  <link name="kinect_depth_optical_frame">
    <inertial>
      <origin xyz="0.0 0.0 0.0"/>
      <mass value="0.001"/>
      <inertia ixx="1.0E-6" ixy="0" ixz="0" iyy="1.0E-6" iyz="0" izz="1.0E-6"/>
    </inertial>
  </link>
  <link name="kinect_rgb_frame">
    <inertial>
      <origin xyz="0.0 0.0 0.0"/>
      <mass value="0.001"/>
      <inertia ixx="1.0E-6" ixy="0" ixz="0" iyy="1.0E-6" iyz="0" izz="1.0E-6"/>
    </inertial>
  </link>
  <link name="kinect_rgb_optical_frame">
    <inertial>
      <origin xyz="0.0 0.0 0.0"/>
      <mass value="0.001"/>
      <inertia ixx="1.0E-6" ixy="0" ixz="0" iyy="1.0E-6" iyz="0" izz="1.0E-6"/>
    </inertial>
  </link>
  <joint name="kinect_joint" type="fixed">
    <parent link="kinect_link"/>
    <child link="kinect_frame"/>
    <origin rpy="0.0 0.0 0.0" xyz="0.01784 0.0 0.02167"/>
  </joint>
  <joint name="kinect_optical_joint" type="fixed">
    <parent link="kinect_frame"/>
    <child link="kinect_optical_frame"/>
    <origin rpy="-1.5708 0.0 -1.5708" xyz="0.0 0.0 0.0"/>
  </joint>
  <joint name="kinect_depth_joint" type="fixed">
    <parent link="kinect_frame"/>
    <child link="kinect_depth_frame"/>
    <origin rpy="0.0 0.0 0.0" xyz="0.0 0.044 0.0"/>
  </joint>
  <joint name="kinect_depth_optical_joint" type="fixed">
    <parent link="kinect_depth_frame"/>
    <child link="kinect_depth_optical_frame"/>
    <origin rpy="-1.5708 0.0 -1.5708" xyz="0.0 0.0 0.0"/>
  </joint>
  <joint name="kinect_rgb_joint" type="fixed">
    <parent link="kinect_frame"/>
    <child link="kinect_rgb_frame"/>
    <origin rpy="0.0 0.0 0.0" xyz="0.0 0.019 0.0"/>
  </joint>
  <joint name="kinect_rgb_optical_joint" type="fixed">
    <parent link="kinect_rgb_frame"/>
    <child link="kinect_rgb_optical_frame"/>
    <origin rpy="-1.5708 0.0 -1.5708" xyz="0.0 0.0 0.0"/>
  </joint>
  <link name="flir_link">
    <inertial>
      <origin xyz="0.00126 0.0 0.0"/>
      <mass value="0.005"/>
      <inertia ixx="2.1208E-7" ixy="0" ixz="0" iyy="4.033E-7" iyz="0" izz="2.1208E-7"/>
    </inertial>
    <visual>
      <geometry>
        <mesh filename="package://pandora_sensors_description/thermal/meshes/flir_lepton.dae"/>
      </geometry>
    </visual>
    <collision>
      <origin rpy="0 0 0" xyz="0.00225 0.0 0.0"/>
      <geometry>
        <box size="0.004 0.020 0.037"/>
      </geometry>
    </collision>
  </link>
  <joint name="flir_parent_joint" type="fixed">
    <parent link="kinect_link"/>
    <child link="flir_link"/>
    <origin rpy="0 0 0" xyz="0.0173 0.0747 0.0"/>
  </joint>
  <link name="flir_frame">
    <inertial>
      <origin xyz="0.0 0.0 0.0"/>
      <mass value="0.001"/>
      <inertia ixx="1.0E-6" ixy="0" ixz="0" iyy="1.0E-6" iyz="0" izz="1.0E-6"/>
    </inertial>
  </link>
  <link name="flir_optical_frame">
    <inertial>
      <origin xyz="0.0 0.0 0.0"/>
      <mass value="0.001"/>
      <inertia ixx="1.0E-6" ixy="0" ixz="0" iyy="1.0E-6" iyz="0" izz="1.0E-6"/>
    </inertial>
  </link>
  <joint name="flir_joint" type="fixed">
    <parent link="flir_link"/>
    <child link="flir_frame"/>
    <origin rpy="0.0 0.0 0.0" xyz="0.0045 0.0 0.00125"/>
  </joint>
  <joint name="flir_optical_joint" type="fixed">
    <parent link="flir_frame"/>
    <child link="flir_optical_frame"/>
    <origin rpy="-1.5708 0.0 -1.5708" xyz="0.0 0.0 0.0"/>
  </joint>
  <link name="left_camera_link">
    <inertial>
      <origin xyz="0.00972 0.0 0.04428"/>
      <mass value="0.005"/>
      <inertia ixx="2.1208E-7" ixy="0" ixz="0" iyy="4.033E-7" iyz="0" izz="2.1208E-7"/>
    </inertial>
    <visual>
      <geometry>
        <mesh filename="package://pandora_sensors_description/webcam/meshes/logitech_c310hd.dae"/>
      </geometry>
    </visual>
    <collision>
      <origin rpy="0 0 0" xyz="0.00557 0.0 0.03624"/>
      <geometry>
        <box size="0.049 0.095 0.073"/>
      </geometry>
    </collision>
  </link>
  <joint name="left_camera_parent_joint" type="fixed">
    <parent link="base_link"/>
    <child link="left_camera_link"/>
    <origin rpy="0.0 0.0 2.356194489" xyz="-0.08308 0.08308 0.23081"/>
  </joint>
  <link name="left_camera_frame">
    <inertial>
      <origin xyz="0.0 0.0 0.0"/>
      <mass value="0.001"/>
      <inertia ixx="1.0E-6" ixy="0" ixz="0" iyy="1.0E-6" iyz="0" izz="1.0E-6"/>
    </inertial>
  </link>
  <link name="left_camera_optical_frame">
    <inertial>
      <origin xyz="0.0 0.0 0.0"/>
      <mass value="0.001"/>
      <inertia ixx="1.0E-6" ixy="0" ixz="0" iyy="1.0E-6" iyz="0" izz="1.0E-6"/>
    </inertial>
  </link>
  <joint name="left_camera_joint" type="fixed">
    <parent link="left_camera_link"/>
    <child link="left_camera_frame"/>
    <origin rpy="0.0 -0.2792 0.0" xyz="0.02499 0.0 0.05704"/>
  </joint>
  <joint name="left_camera_optical_joint" type="fixed">
    <parent link="left_camera_frame"/>
    <child link="left_camera_optical_frame"/>
    <origin rpy="-1.5708 0.0 -1.5708" xyz="0.0 0.0 0.0"/>
  </joint>
  <link name="right_camera_link">
    <inertial>
      <origin xyz="0.00972 0.0 0.04428"/>
      <mass value="0.005"/>
      <inertia ixx="2.1208E-7" ixy="0" ixz="0" iyy="4.033E-7" iyz="0" izz="2.1208E-7"/>
    </inertial>
    <visual>
      <geometry>
        <mesh filename="package://pandora_sensors_description/webcam/meshes/logitech_c310hd.dae"/>
      </geometry>
    </visual>
    <collision>
      <origin rpy="0 0 0" xyz="0.00557 0.0 0.03624"/>
      <geometry>
        <box size="0.049 0.095 0.073"/>
      </geometry>
    </collision>
  </link>
  <joint name="right_camera_parent_joint" type="fixed">
    <parent link="base_link"/>
    <child link="right_camera_link"/>
    <origin rpy="0.0 0.0 3.926990815" xyz="-0.08308 -0.08308 0.23081"/>
  </joint>
  <link name="right_camera_frame">
    <inertial>
      <origin xyz="0.0 0.0 0.0"/>
      <mass value="0.001"/>
      <inertia ixx="1.0E-6" ixy="0" ixz="0" iyy="1.0E-6" iyz="0" izz="1.0E-6"/>
    </inertial>
  </link>
  <link name="right_camera_optical_frame">
    <inertial>
      <origin xyz="0.0 0.0 0.0"/>
      <mass value="0.001"/>
      <inertia ixx="1.0E-6" ixy="0" ixz="0" iyy="1.0E-6" iyz="0" izz="1.0E-6"/>
    </inertial>
  </link>
  <joint name="right_camera_joint" type="fixed">
    <parent link="right_camera_link"/>
    <child link="right_camera_frame"/>
    <origin rpy="0.0 -0.2792 0.0" xyz="0.02499 0.0 0.05704"/>
  </joint>
  <joint name="right_camera_optical_joint" type="fixed">
    <parent link="right_camera_frame"/>
    <child link="right_camera_optical_frame"/>
    <origin rpy="-1.5708 0.0 -1.5708" xyz="0.0 0.0 0.0"/>
  </joint>
  <link name="left_sonar_link">
    <inertial>
      <origin xyz="0.005 0.0 0.0"/>
      <mass value="0.010"/>
      <inertia ixx="4.2416E-7" ixy="0.0" ixz="0.0" iyy="2.0166E-6" iyz="0.0" izz="1.6341E-6"/>
    </inertial>
    <visual>
      <geometry>
        <mesh filename="package://pandora_sensors_description/sonar/meshes/devantech_srf05.dae"/>
      </geometry>
    </visual>
    <collision>
      <origin rpy="0 0 0" xyz="0.0075 0.0 0.0"/>
      <geometry>
        <box size="0.015 0.044 0.022"/>
      </geometry>
    </collision>
  </link>
  <joint name="left_sonar_parent_joint" type="fixed">
    <parent link="base_link"/>
    <child link="left_sonar_link"/>
    <origin rpy="0.0 0.0 -0.523598776" xyz="-0.146 0.1376 0.21406"/>
  </joint>
  <link name="left_sonar_frame">
    <inertial>
      <origin xyz="0.0 0.0 0.0"/>
      <mass value="0.001"/>
      <inertia ixx="1.0E-6" ixy="0" ixz="0" iyy="1.0E-6" iyz="0" izz="1.0E-6"/>
    </inertial>
  </link>
  <joint name="left_sonar_joint" type="fixed">
    <parent link="left_sonar_link"/>
    <child link="left_sonar_frame"/>
    <origin rpy="0.0 0.0 0.0" xyz="0.015 0.0 0.0"/>
  </joint>
  <link name="right_sonar_link">
    <inertial>
      <origin xyz="0.005 0.0 0.0"/>
      <mass value="0.010"/>
      <inertia ixx="4.2416E-7" ixy="0.0" ixz="0.0" iyy="2.0166E-6" iyz="0.0" izz="1.6341E-6"/>
    </inertial>
    <visual>
      <geometry>
        <mesh filename="package://pandora_sensors_description/sonar/meshes/devantech_srf05.dae"/>
      </geometry>
    </visual>
    <collision>
      <origin rpy="0 0 0" xyz="0.0075 0.0 0.0"/>
      <geometry>
        <box size="0.015 0.044 0.022"/>
      </geometry>
    </collision>
  </link>
  <joint name="right_sonar_parent_joint" type="fixed">
    <parent link="base_link"/>
    <child link="right_sonar_link"/>
    <origin rpy="0.0 0.0 0.523598776" xyz="-0.146 -0.1376 0.21406"/>
  </joint>
  <link name="right_sonar_frame">
    <inertial>
      <origin xyz="0.0 0.0 0.0"/>
      <mass value="0.001"/>
      <inertia ixx="1.0E-6" ixy="0" ixz="0" iyy="1.0E-6" iyz="0" izz="1.0E-6"/>
    </inertial>
  </link>
  <joint name="right_sonar_joint" type="fixed">
    <parent link="right_sonar_link"/>
    <child link="right_sonar_frame"/>
    <origin rpy="0.0 0.0 0.0" xyz="0.015 0.0 0.0"/>
  </joint>
  <link name="co2_link">
    <inertial>
      <origin xyz="0.005 0.0 0.0"/>
      <mass value="0.005"/>
      <inertia ixx="2.1208E-7" ixy="0" ixz="0" iyy="4.033E-7" iyz="0" izz="2.1208E-7"/>
    </inertial>
    <visual>
      <geometry>
        <mesh filename="package://pandora_sensors_description/co2/meshes/dynament_gold.dae"/>
      </geometry>
    </visual>
    <collision>
      <origin rpy="0 0 0" xyz="0.0075 0.0 0.0"/>
      <geometry>
        <box size="0.015 0.022 0.022"/>
      </geometry>
    </collision>
  </link>
  <joint name="co2_parent_joint" type="fixed">
    <parent link="kinect_link"/>
    <child link="co2_link"/>
    <origin rpy="0.0 0.0 0.0" xyz="0.0173 -0.0595 0.0"/>
  </joint>
  <link name="co2_frame">
    <inertial>
      <origin xyz="0.0 0.0 0.0"/>
      <mass value="0.001"/>
      <inertia ixx="1.0E-6" ixy="0" ixz="0" iyy="1.0E-6" iyz="0" izz="1.0E-6"/>
    </inertial>
  </link>
  <joint name="co2_joint" type="fixed">
    <parent link="co2_link"/>
    <child link="co2_frame"/>
    <origin rpy="0.0 0.0 0.0" xyz="0.015 0.0 0.0"/>
  </joint>
  <gazebo reference="left_front_wheel_link">
    <minDepth>0.001</minDepth>
    <mu1>0.75</mu1>
    <mu2>0.75</mu2>
    <fdir1>1 0 0</fdir1>
    <kp>1000000.0</kp>
    <kd>1.0</kd>
    <maxContacts>10</maxContacts>
  </gazebo>
  <gazebo reference="left_rear_wheel_link">
    <minDepth>0.001</minDepth>
    <mu1>0.75</mu1>
    <mu2>0.75</mu2>
    <fdir1>1 0 0</fdir1>
    <kp>1000000.0</kp>
    <kd>1.0</kd>
    <maxContacts>10</maxContacts>
  </gazebo>
  <gazebo reference="right_front_wheel_link">
    <minDepth>0.001</minDepth>
    <mu1>0.75</mu1>
    <mu2>0.75</mu2>
    <fdir1>1 0 0</fdir1>
    <kp>1000000.0</kp>
    <kd>1.0</kd>
    <maxContacts>10</maxContacts>
  </gazebo>
  <gazebo reference="right_rear_wheel_link">
    <minDepth>0.001</minDepth>
    <mu1>0.75</mu1>
    <mu2>0.75</mu2>
    <fdir1>1 0 0</fdir1>
    <kp>1000000.0</kp>
    <kd>1.0</kd>
    <maxContacts>10</maxContacts>
  </gazebo>
  <gazebo reference="left_side_joint">
    <implicitSpringDamper>true</implicitSpringDamper>
  </gazebo>
  <gazebo reference="right_side_joint">
    <implicitSpringDamper>true</implicitSpringDamper>
  </gazebo>
  <gazebo reference="laser_roll_joint">
    <implicitSpringDamper>true</implicitSpringDamper>
  </gazebo>
  <gazebo reference="laser_pitch_joint">
    <implicitSpringDamper>true</implicitSpringDamper>
  </gazebo>
  <gazebo reference="kinect_pitch_joint">
    <implicitSpringDamper>true</implicitSpringDamper>
  </gazebo>
  <gazebo reference="kinect_yaw_joint">
    <implicitSpringDamper>true</implicitSpringDamper>
  </gazebo>
  <!-- Load URDF -->
  <xacro:woody_urdf/>
  <!-- Load gazebo sensors -->
  <gazebo reference="laser_link">
    <sensor name="laser" type="ray">
      <ray>
        <scan>
          <horizontal>
            <samples>683</samples>
            <resolution>1</resolution>
            <min_angle>-2.26889</min_angle>
            <max_angle>2.268899</max_angle>
          </horizontal>
        </scan>
        <range>
          <min>0.08</min>
          <max>4</max>
          <resolution>0.01</resolution>
        </range>
      </ray>
      <plugin filename="libRayPlugin.so" name="laser"/>
      <plugin filename="libgazebo_ros_laser.so" name="laser2Ros">
        <frameName>/laser_link</frameName>
        <topicName>/laser/scan</topicName>
      </plugin>
      <always_on>1</always_on>
      <update_rate>10</update_rate>
      <visualize>true</visualize>
    </sensor>
  </gazebo>
  <gazebo reference="kinect_frame">
    <sensor name="kinect" type="depth">
      <camera>
        <horizontal_fov>1.012290966</horizontal_fov>
        <image>
          <width>640</width>
          <height>480</height>
          <format>R8G8B8</format>
        </image>
        <clip>
          <near>0.3</near>
          <far>3</far>
        </clip>
      </camera>
      <plugin filename="libgazebo_ros_openni_kinect.so" name="depth2ros">
        <frameName>kinect_depth_optical_frame</frameName>
        <cameraName>kinect</cameraName>
        <pointCloudTopicName>depth_registered/points</pointCloudTopicName>
        <imageTopicName>rgb/image_raw</imageTopicName>
        <depthImageTopicName>depth/image</depthImageTopicName>
        <depthImageCameraInfoTopicName>depth/image/info</depthImageCameraInfoTopicName>
        <pointCloudCutoff>0.4</pointCloudCutoff>
      </plugin>
      <always_on>1</always_on>
      <update_rate>25</update_rate>
      <visualize>true</visualize>
    </sensor>
  </gazebo>
  <xacro:thermal_sensor/>
  <gazebo reference="left_camera_frame">
    <sensor name="left_camera" type="camera">
      <camera>
        <horizontal_fov>1.047197551</horizontal_fov>
        <image>
          <width>1280</width>
          <height>720</height>
          <format>R8G8B8</format>
        </image>
        <clip>
          <near>0.15</near>
          <far>2.0</far>
        </clip>
      </camera>
      <plugin filename="libgazebo_ros_camera.so" name="camera2ros">
        <frameName>left_camera_optical_frame</frameName>
        <cameraName>left_camera</cameraName>
        <imageTopicName>image</imageTopicName>
      </plugin>
      <always_on>1</always_on>
      <update_rate>5</update_rate>
      <visualize>false</visualize>
    </sensor>
  </gazebo>
  <gazebo reference="right_camera_frame">
    <sensor name="right_camera" type="camera">
      <camera>
        <horizontal_fov>1.047197551</horizontal_fov>
        <image>
          <width>1280</width>
          <height>720</height>
          <format>R8G8B8</format>
        </image>
        <clip>
          <near>0.15</near>
          <far>2.0</far>
        </clip>
      </camera>
      <plugin filename="libgazebo_ros_camera.so" name="camera2ros">
        <frameName>right_camera_optical_frame</frameName>
        <cameraName>right_camera</cameraName>
        <imageTopicName>image</imageTopicName>
      </plugin>
      <always_on>1</always_on>
      <update_rate>5</update_rate>
      <visualize>false</visualize>
    </sensor>
  </gazebo>
  <gazebo reference="middle_thermal_frame">
    <sensor name="middle_thermal" type="camera">
      <camera>
        <horizontal_fov>0.8</horizontal_fov>
        <image>
          <width>8</width>
          <height>8</height>
        </image>
        <clip>
          <near>0.05</near>
          <far>1.5</far>
        </clip>
      </camera>
      <plugin filename="libpandora_gazebo_plugins_pandora_thermal_plugin.so" name="thermal2ros">
        <robotNamespace>gazebo_sensors</robotNamespace>
        <frameName>middle_thermal_optical_frame</frameName>
        <topicName>thermal</topicName>
      </plugin>
      <always_on>1</always_on>
      <update_rate>4</update_rate>
      <visualize>false</visualize>
    </sensor>
  </gazebo>
  <gazebo reference="left_thermal_frame">
    <sensor name="left_thermal" type="camera">
      <camera>
        <horizontal_fov>0.8</horizontal_fov>
        <image>
          <width>8</width>
          <height>8</height>
        </image>
        <clip>
          <near>0.05</near>
          <far>1.5</far>
        </clip>
      </camera>
      <plugin filename="libpandora_gazebo_plugins_pandora_thermal_plugin.so" name="thermal2ros">
        <robotNamespace>gazebo_sensors</robotNamespace>
        <frameName>left_thermal_optical_frame</frameName>
        <topicName>thermal</topicName>
      </plugin>
      <always_on>1</always_on>
      <update_rate>4</update_rate>
      <visualize>false</visualize>
    </sensor>
  </gazebo>
  <gazebo reference="right_thermal_frame">
    <sensor name="right_thermal" type="camera">
      <camera>
        <horizontal_fov>0.8</horizontal_fov>
        <image>
          <width>8</width>
          <height>8</height>
        </image>
        <clip>
          <near>0.05</near>
          <far>1.5</far>
        </clip>
      </camera>
      <plugin filename="libpandora_gazebo_plugins_pandora_thermal_plugin.so" name="thermal2ros">
        <robotNamespace>gazebo_sensors</robotNamespace>
        <frameName>right_thermal_optical_frame</frameName>
        <topicName>thermal</topicName>
      </plugin>
      <always_on>1</always_on>
      <update_rate>4</update_rate>
      <visualize>false</visualize>
    </sensor>
  </gazebo>
  <!-- Load Plugins -->
  <gazebo>
    <plugin filename="libgazebo_ros_control.so" name="GazeboRosControl">
      <robotSimType>pandora_gazebo_interface/WoodyGazeboInterface</robotSimType>
    </plugin>
  </gazebo>
  <gazebo>
    <plugin filename="libpandora_gazebo_plugins_pandora_differential_plugin.so" name="PandoraDifferantialPlugin">
      <robotNamespace>/</robotNamespace>
      <publishJointStates>false</publishJointStates>
      <baseLink>base_link</baseLink>
      <leftSideJoint>left_side_joint</leftSideJoint>
      <rightSideJoint>right_side_joint</rightSideJoint>
      <leftFrontWheelLink>left_front_wheel_link</leftFrontWheelLink>
      <leftRearWheelLink>left_rear_wheel_link</leftRearWheelLink>
      <rightFrontWheelLink>right_front_wheel_link</rightFrontWheelLink>
      <rightRearWheelLink>right_rear_wheel_link</rightRearWheelLink>
      <maxAngle>0.785</maxAngle>
      <sideJointDamping>0.0</sideJointDamping>
      <P>120.0</P>
      <I>0.005</I>
      <D>8.0</D>
      <correctionForceModifier>200.0</correctionForceModifier>
      <maxDownforce>0.0</maxDownforce>
      <maxDifferentialForceZ>0.0</maxDifferentialForceZ>
      <maxDifferentialForceY>0.0</maxDifferentialForceY>
    </plugin>
  </gazebo>
  <gazebo>
    <plugin filename="libpandora_gazebo_plugins_pandora_p3d_plugin.so" name="Pandora3dPosePlugin">
      <robotNamespace>/</robotNamespace>
      <bodyName>base_link</bodyName>
      <frameName>map</frameName>
      <topicName>perfect_pose</topicName>
      <broadcastTF>0</broadcastTF>
    </plugin>
  </gazebo>
  <gazebo>
    <plugin filename="libpandora_gazebo_plugins_pandora_wheel_physics_plugin.so" name="PandoraWheelPhysicsPlugin">
      <robotNamespace>/</robotNamespace>
      <leftFrontWheelLink>left_front_wheel_link</leftFrontWheelLink>
      <leftRearWheelLink>left_rear_wheel_link</leftRearWheelLink>
      <rightFrontWheelLink>right_front_wheel_link</rightFrontWheelLink>
      <rightRearWheelLink>right_rear_wheel_link</rightRearWheelLink>
    </plugin>
  </gazebo>
</robot>

